<?xml version="1.0"?>
<!-- This URDF was automatically created by SolidWorks to URDF Exporter! Originally created by Stephen Brawner (brawner@gmail.com)
     Commit Version: 1.6.0-4-g7f85cfe  Build Version: 1.6.7995.38578
     For more information, please see http://wiki.ros.org/sw_urdf_exporter -->
<robot
  name="TianXun">

  <!-- <mujoco>
		<compiler
		meshdir="package://xpp_eqr2/meshes"
		balanceinertia="true"
		discardvisual="false"/>
	</mujoco> -->


	<!-- <link name="world"></link>

	<joint name="floating_base_joint" type="floating">
		<parent link="world" />
		<child link="base_link" />
	</joint> -->

  <link
    name="base_link">
    <inertial>
      <origin
        xyz="-0.00044 7E-05 -0.02296"
        rpy="0 0 0" />
      <mass
        value="20.875" />
      <inertia
        ixx="0.16228"
        ixy="-0.00013"
        ixz="-0.00213"
        iyy="0.70163"
        iyz="5E-05"
        izz="0.77171" />
    </inertial>
    <visual>
      <origin
        xyz="0 0 0"
        rpy="0 0 0" />
      <geometry>
        <mesh
          filename="package://xpp_eqr2/meshes/base_link.STL" />
      </geometry>
      <material
        name="">
        <color
          rgba="0.75294 0.75294 0.75294 1" />
      </material>
    </visual>
    <collision>
      <origin
        xyz="0 0 -0.02"
        rpy="0 0 0" />
      <geometry>
        <box
          size="0.25 0.28 0.21" />
      </geometry>
    </collision>

    <collision>
      <origin
        xyz="0.13 0.075 -0.135"
        rpy="0 0 0" />
      <geometry>
        <box
          size="0.02 0.01 0.015" />
      </geometry>
    </collision>

    <collision>
      <origin
        xyz="-0.13 0.075 -0.135"
        rpy="0 0 0" />
      <geometry>
        <box
          size="0.02 0.01 0.015" />
      </geometry>
    </collision>

    <collision>
      <origin
        xyz="0.13 -0.075 -0.135"
        rpy="0 0 0" />
      <geometry>
        <box
          size="0.02 0.01 0.015" />
      </geometry>
    </collision>

    <collision>
      <origin
        xyz="-0.13 -0.075 -0.135"
        rpy="0 0 0" />
      <geometry>
        <box
          size="0.02 0.01 0.015" />
      </geometry>
    </collision>

  </link>
  <link
    name="fl_leg_l1">
    <inertial>
      <origin
        xyz="0.069911 0.0090275 0"
        rpy="0 0 0" />
      <mass
        value="1.4741" />
      <inertia
        ixx="0.0016643"
        ixy="2E-05"
        ixz="0"
        iyy="0.00306"
        iyz="0"
        izz="0.002" />
    </inertial>
    <visual>
      <origin
        xyz="0 0 0"
        rpy="0 0 0" />
      <geometry>
        <mesh
          filename="package://xpp_eqr2/meshes/fl_leg_l1.STL" />
      </geometry>
      <material
        name="">
        <color
          rgba="0.75294 0.75294 0.75294 1" />
      </material>
    </visual>
    <collision>
      <origin
        xyz="0.072 0.005 0"
        rpy="1.5708 0 0" />
      <geometry>
        <cylinder
          radius="0.065"
          length="0.045" />
      </geometry>
    </collision>
  </link>
  <joint
    name="fl_leg_1"
    type="revolute">
    <origin
      xyz="0.2375 0.0625 -0.0225"
      rpy="0 0 0" />
    <parent
      link="base_link" />
    <child
      link="fl_leg_l1" />
    <axis
      xyz="1 0 0" />
    <limit
      lower="-0.838"
      upper="0.838"
      effort="130"
      velocity="20" />
  </joint>
  <link
    name="fl_leg_l2">
    <inertial>
      <origin
        xyz="-0.027742 0.092021 0.0050821"
        rpy="0 0 0" />
      <mass
        value="2.7391" />
      <inertia
        ixx="0.00552"
        ixy="-0.0028"
        ixz="-0.00152"
        iyy="0.01658"
        iyz="0.00051"
        izz="0.01673" />
    </inertial>
    <visual>
      <origin
        xyz="0 0 0"
        rpy="0 0 0" />
      <geometry>
        <mesh
          filename="package://xpp_eqr2/meshes/fl_leg_l2.STL" />
      </geometry>
      <material
        name="">
        <color
          rgba="0.75294 0.75294 0.75294 1" />
      </material>
    </visual>
    <collision>
      <origin
        xyz="0 0.09 0"
        rpy="1.5708 0 0" />
      <geometry>
        <cylinder
          radius="0.065"
          length="0.12" />
      </geometry>
    </collision>

    <collision>
      <origin
        xyz="-0.13 0.13 0.03"
        rpy="0.0 0 0" />
      <geometry>
        <box
          size="0.11 0.05 0.05" />
      </geometry>
    </collision>

  </link>
  <joint
    name="fl_leg_2"
    type="revolute">
    <origin
      xyz="0.075 0.00975 0"
      rpy="0 0 0" />
    <parent
      link="fl_leg_l1" />
    <child
      link="fl_leg_l2" />
    <axis
      xyz="0 1 0" />
    <limit
      lower="-3.49"
      upper="1.84"
      effort="150"
      velocity="20" />
  </joint>
  <link
    name="fl_leg_l3">
    <inertial>
      <origin
        xyz="0.091028 -1E-05 -0.028535"
        rpy="0 0 0" />
      <mass
        value="0.37038" />
      <inertia
        ixx="0.00068"
        ixy="0"
        ixz="-0.00143"
        iyy="0.00433"
        iyz="0"
        izz="0.0037" />
    </inertial>
    <visual>
      <origin
        xyz="0 0 0"
        rpy="0 0 0" />
      <geometry>
        <mesh
          filename="package://xpp_eqr2/meshes/fl_leg_l3.STL" />
      </geometry>
      <material
        name="">
        <color
          rgba="0.75294 0.75294 0.75294 1" />
      </material>
    </visual>

    <collision>
      <origin
        xyz="0.1 0 -0.02"
        rpy="0 0 0" />
      <geometry>
        <box
          size="0.08 0.02 0.025" />
      </geometry>
    </collision>

    <collision>
      <origin
        xyz="0.18 0 -0.05"
        rpy="0 0.70 0" />
      <geometry>
        <box
          size="0.08 0.02 0.025" />
      </geometry>
    </collision>

    <collision>
      <origin
        xyz="0.025 0 -0.01"
        rpy="0 0.26 0" />
      <geometry>
        <box
          size="0.063 0.025 0.025" />
      </geometry>
    </collision>

    <collision>
      <origin
        xyz="-0.025 0 0.02"
        rpy="0 1.0 0" />
      <geometry>
        <box
          size="0.04 0.02 0.025" />
      </geometry>
    </collision>

  </link>
  <joint
    name="fl_leg_3"
    type="revolute">
    <origin
      xyz="-0.25 0.12675 0"
      rpy="0 0 0" />
    <parent
      link="fl_leg_l2" />
    <child
      link="fl_leg_l3" />
    <axis
      xyz="0 1 0" />
    <limit
      lower="0"
      upper="1.86"
      effort="150"
      velocity="20" />
  </joint>
  <link
    name="fl_leg_lee">
    <inertial>
      <origin
        xyz="0.0055825 0.0001816 -0.011846"
        rpy="0 0 0" />
      <mass
        value="0.10556" />
      <inertia
        ixx="2E-05"
        ixy="0"
        ixz="1E-05"
        iyy="3E-05"
        iyz="0"
        izz="4E-05" />
    </inertial>
    <visual>
      <origin
        xyz="0 0 0"
        rpy="0 0 0" />
      <geometry>
        <mesh
          filename="package://xpp_eqr2/meshes/fl_leg_lee.STL" />
      </geometry>
      <material
        name="">
        <color
          rgba="0.75294 0.75294 0.75294 1" />
      </material>
    </visual>

    <collision>
      <origin
        xyz="0 0 0" rpy="0 0 0" />
      <geometry>
        <sphere
          radius="0.035" />
      </geometry>
    </collision>

  </link>
  <joint
    name="fl_leg_ee"
    type="fixed">
    <origin
      xyz="0.25045 0 -0.11113"
      rpy="0 0 0" />
    <parent
      link="fl_leg_l3" />
    <child
      link="fl_leg_lee" />
    <axis
      xyz="0 0 0" />
  </joint>
  <link
    name="fr_leg_l1">
    <inertial>
      <origin
        xyz="0.069911 -0.0090275 -5.0015E-08"
        rpy="0 0 0" />
      <mass
        value="1.4741" />
      <inertia
        ixx="0.0016643"
        ixy="-2E-05"
        ixz="0"
        iyy="0.00306"
        iyz="0"
        izz="0.002" />
    </inertial>
    <visual>
      <origin
        xyz="0 0 0"
        rpy="0 0 0" />
      <geometry>
        <mesh
          filename="package://xpp_eqr2/meshes/fr_leg_l1.STL" />
      </geometry>
      <material
        name="">
        <color
          rgba="0.75294 0.75294 0.75294 1" />
      </material>
    </visual>
    <collision>
      <origin
        xyz="0.072 -0.005 0"
        rpy="1.5708 0 0" />
      <geometry>
        <cylinder
          radius="0.065"
          length="0.045" />
      </geometry>
    </collision>
  </link>
  <joint
    name="fr_leg_1"
    type="revolute">
    <origin
      xyz="0.2375 -0.0625 -0.0225"
      rpy="0 0 0" />
    <parent
      link="base_link" />
    <child
      link="fr_leg_l1" />
    <axis
      xyz="1 0 0" />
    <limit
      lower="-0.838"
      upper="0.838"
      effort="130"
      velocity="20" />
  </joint>
  <link
    name="fr_leg_l2">
    <inertial>
      <origin
        xyz="-0.027489 -0.092021 0.0051936"
        rpy="0 0 0" />
      <mass
        value="2.739" />
      <inertia
        ixx="0.00554"
        ixy="0.00278"
        ixz="-0.00146"
        iyy="0.01645"
        iyz="-0.00053"
        izz="0.01659" />
    </inertial>
    <visual>
      <origin
        xyz="0 0 0"
        rpy="0 0 0" />
      <geometry>
        <mesh
          filename="package://xpp_eqr2/meshes/fr_leg_l2.STL" />
      </geometry>
      <material
        name="">
        <color
          rgba="0.75294 0.75294 0.75294 1" />
      </material>
    </visual>
    <collision>
      <origin
        xyz="0 -0.09 0"
        rpy="1.5708 0 0" />
      <geometry>
        <cylinder
          radius="0.065"
          length="0.12" />
      </geometry>
    </collision>

    <collision>
      <origin
        xyz="-0.13 -0.13 0.03"
        rpy="0.0 0 0" />
      <geometry>
        <box
          size="0.11 0.05 0.05" />
      </geometry>
    </collision>
  </link>
  <joint
    name="fr_leg_2"
    type="revolute">
    <origin
      xyz="0.075 -0.00975 0"
      rpy="0 0 0" />
    <parent
      link="fr_leg_l1" />
    <child
      link="fr_leg_l2" />
    <axis
      xyz="0 1 0" />
    <limit
      lower="-3.49"
      upper="1.84"
      effort="150"
      velocity="20" />
  </joint>
  <link
    name="fr_leg_l3">
    <inertial>
      <origin
        xyz="0.091028 -5.4257E-06 -0.028535"
        rpy="0 0 0" />
      <mass
        value="0.37038" />
      <inertia
        ixx="0.00068"
        ixy="0"
        ixz="-0.00143"
        iyy="0.00433"
        iyz="0"
        izz="0.0037" />
    </inertial>
    <visual>
      <origin
        xyz="0 0 0"
        rpy="0 0 0" />
      <geometry>
        <mesh
          filename="package://xpp_eqr2/meshes/fr_leg_l3.STL" />
      </geometry>
      <material
        name="">
        <color
          rgba="0.75294 0.75294 0.75294 1" />
      </material>
    </visual>
    <collision>
      <origin
        xyz="0.1 0 -0.02"
        rpy="0 0 0" />
      <geometry>
        <box
          size="0.08 0.02 0.025" />
      </geometry>
    </collision>

    <collision>
      <origin
        xyz="0.18 0 -0.05"
        rpy="0 0.70 0" />
      <geometry>
        <box
          size="0.08 0.02 0.025" />
      </geometry>
    </collision>

    <collision>
      <origin
        xyz="0.025 0 -0.01"
        rpy="0 0.26 0" />
      <geometry>
        <box
          size="0.063 0.025 0.025" />
      </geometry>
    </collision>

    <collision>
      <origin
        xyz="-0.025 0 0.02"
        rpy="0 1.0 0" />
      <geometry>
        <box
          size="0.04 0.02 0.025" />
      </geometry>
    </collision>

  </link>
  <joint
    name="fr_leg_3"
    type="revolute">
    <origin
      xyz="-0.25 -0.12675 0"
      rpy="0 0 0" />
    <parent
      link="fr_leg_l2" />
    <child
      link="fr_leg_l3" />
    <axis
      xyz="0 1 0" />
    <limit
      lower="0"
      upper="1.86"
      effort="150"
      velocity="20" />
  </joint>
  <link
    name="fr_leg_lee">
    <inertial>
      <origin
        xyz="0.0055825 0.0001816 -0.011846"
        rpy="0 0 0" />
      <mass
        value="0.10556" />
      <inertia
        ixx="2E-05"
        ixy="0"
        ixz="1E-05"
        iyy="3E-05"
        iyz="0"
        izz="4E-05" />
    </inertial>
    <visual>
      <origin
        xyz="0 0 0"
        rpy="0 0 0" />
      <geometry>
        <mesh
          filename="package://xpp_eqr2/meshes/fr_leg_lee.STL" />
      </geometry>
      <material
        name="">
        <color
          rgba="0.75294 0.75294 0.75294 1" />
      </material>
    </visual>
    <collision>
      <origin
        xyz="0 0 0" rpy="0 0 0" />
      <geometry>
        <sphere
          radius="0.035" />
      </geometry>
    </collision>
  </link>
  <joint
    name="fr_leg_ee"
    type="fixed">
    <origin
      xyz="0.25045 0 -0.11113"
      rpy="0 0 0" />
    <parent
      link="fr_leg_l3" />
    <child
      link="fr_leg_lee" />
    <axis
      xyz="0 0 0" />
  </joint>
  <link
    name="hl_leg_l1">
    <inertial>
      <origin
        xyz="-0.069911 0.0090275 0"
        rpy="0 0 0" />
      <mass
        value="1.4741" />
      <inertia
        ixx="0.0016643"
        ixy="-2E-05"
        ixz="0"
        iyy="0.00306"
        iyz="0"
        izz="0.002" />
    </inertial>
    <visual>
      <origin
        xyz="0 0 0"
        rpy="0 0 0" />
      <geometry>
        <mesh
          filename="package://xpp_eqr2/meshes/hl_leg_l1.STL" />
      </geometry>
      <material
        name="">
        <color
          rgba="0.75294 0.75294 0.75294 1" />
      </material>
    </visual>
    <collision>
      <origin
        xyz="-0.072 0.005 0"
        rpy="1.5708 0 0" />
      <geometry>
        <cylinder
          radius="0.065"
          length="0.045" />
      </geometry>
    </collision>
  </link>
  <joint
    name="hl_leg_1"
    type="revolute">
    <origin
      xyz="-0.2385 0.0625 -0.0225"
      rpy="0 0 0" />
    <parent
      link="base_link" />
    <child
      link="hl_leg_l1" />
    <axis
      xyz="1 0 0" />
    <limit
      lower="-0.838"
      upper="0.838"
      effort="130"
      velocity="20" />
  </joint>
  <link
    name="hl_leg_l2">
    <inertial>
      <origin
        xyz="-0.027742 0.092021 0.0050821"
        rpy="0 0 0" />
      <mass
        value="2.7391" />
      <inertia
        ixx="0.00552"
        ixy="-0.0028"
        ixz="-0.00152"
        iyy="0.01658"
        iyz="0.00051"
        izz="0.01673" />
    </inertial>
    <visual>
      <origin
        xyz="0 0 0"
        rpy="0 0 0" />
      <geometry>
        <mesh
          filename="package://xpp_eqr2/meshes/hl_leg_l2.STL" />
      </geometry>
      <material
        name="">
        <color
          rgba="0.75294 0.75294 0.75294 1" />
      </material>
    </visual>
    <collision>
      <origin
        xyz="0 0.09 0"
        rpy="1.5708 0 0" />
      <geometry>
        <cylinder
          radius="0.065"
          length="0.12" />
      </geometry>
    </collision>

    <collision>
      <origin
        xyz="-0.13 0.13 0.03"
        rpy="0.0 0 0" />
      <geometry>
        <box
          size="0.11 0.05 0.05" />
      </geometry>
    </collision>

  </link>
  <joint
    name="hl_leg_2"
    type="revolute">
    <origin
      xyz="-0.075 0.00975 0"
      rpy="0 0 0" />
    <parent
      link="hl_leg_l1" />
    <child
      link="hl_leg_l2" />
    <axis
      xyz="0 1 0" />
    <limit
      lower="-3.49"
      upper="1.84"
      effort="150"
      velocity="20" />
  </joint>
  <link
    name="hl_leg_l3">
    <inertial>
      <origin
        xyz="0.091028 -1E-05 -0.028535"
        rpy="0 0 0" />
      <mass
        value="0.37038" />
      <inertia
        ixx="0.00068"
        ixy="0"
        ixz="-0.00143"
        iyy="0.00433"
        iyz="0"
        izz="0.0037" />
    </inertial>
    <visual>
      <origin
        xyz="0 0 0"
        rpy="0 0 0" />
      <geometry>
        <mesh
          filename="package://xpp_eqr2/meshes/hl_leg_l3.STL" />
      </geometry>
      <material
        name="">
        <color
          rgba="0.75294 0.75294 0.75294 1" />
      </material>
    </visual>
    <collision>
      <origin
        xyz="0.1 0 -0.02"
        rpy="0 0 0" />
      <geometry>
        <box
          size="0.08 0.02 0.025" />
      </geometry>
    </collision>

    <collision>
      <origin
        xyz="0.18 0 -0.05"
        rpy="0 0.70 0" />
      <geometry>
        <box
          size="0.08 0.02 0.025" />
      </geometry>
    </collision>

    <collision>
      <origin
        xyz="0.025 0 -0.01"
        rpy="0 0.26 0" />
      <geometry>
        <box
          size="0.063 0.025 0.025" />
      </geometry>
    </collision>

    <collision>
      <origin
        xyz="-0.025 0 0.02"
        rpy="0 1.0 0" />
      <geometry>
        <box
          size="0.04 0.02 0.025" />
      </geometry>
    </collision>
  </link>
  <joint
    name="hl_leg_3"
    type="revolute">
    <origin
      xyz="-0.25 0.12675 0"
      rpy="0 0 0" />
    <parent
      link="hl_leg_l2" />
    <child
      link="hl_leg_l3" />
    <axis
      xyz="0 1 0" />
    <limit
      lower="0"
      upper="1.86"
      effort="150"
      velocity="20" />
  </joint>
  <link
    name="hl_leg_lee">
    <inertial>
      <origin
        xyz="0.0055825 0.0001816 -0.011846"
        rpy="0 0 0" />
      <mass
        value="0.10556" />
      <inertia
        ixx="2E-05"
        ixy="0"
        ixz="1E-05"
        iyy="3E-05"
        iyz="0"
        izz="4E-05" />
    </inertial>
    <visual>
      <origin
        xyz="0 0 0"
        rpy="0 0 0" />
      <geometry>
        <mesh
          filename="package://xpp_eqr2/meshes/hl_leg_lee.STL" />
      </geometry>
      <material
        name="">
        <color
          rgba="0.75294 0.75294 0.75294 1" />
      </material>
    </visual>
    <collision>
      <origin
        xyz="0 0 0" rpy="0 0 0" />
      <geometry>
        <sphere
          radius="0.035" />
      </geometry>
    </collision>
  </link>
  <joint
    name="hl_leg_ee"
    type="fixed">
    <origin
      xyz="0.25045 0 -0.11113"
      rpy="0 0 0" />
    <parent
      link="hl_leg_l3" />
    <child
      link="hl_leg_lee" />
    <axis
      xyz="0 0 0" />
  </joint>
  <link
    name="hr_leg_l1">
    <inertial>
      <origin
        xyz="-0.069911 -0.0090275 0"
        rpy="0 0 0" />
      <mass
        value="1.4741" />
      <inertia
        ixx="0.00166"
        ixy="2E-05"
        ixz="0"
        iyy="0.00306"
        iyz="0"
        izz="0.002" />
    </inertial>
    <visual>
      <origin
        xyz="0 0 0"
        rpy="0 0 0" />
      <geometry>
        <mesh
          filename="package://xpp_eqr2/meshes/hr_leg_l1.STL" />
      </geometry>
      <material
        name="">
        <color
          rgba="0.75294 0.75294 0.75294 1" />
      </material>
    </visual>
    <collision>
      <origin
        xyz="-0.072 -0.005 0"
        rpy="1.5708 0 0" />
      <geometry>
        <cylinder
          radius="0.065"
          length="0.045" />
      </geometry>
    </collision>
  </link>
  <joint
    name="hr_leg_1"
    type="revolute">
    <origin
      xyz="-0.2385 -0.0625 -0.0225"
      rpy="0 0 0" />
    <parent
      link="base_link" />
    <child
      link="hr_leg_l1" />
    <axis
      xyz="1 0 0" />
    <limit
      lower="-0.838"
      upper="0.838"
      effort="130"
      velocity="20" />
  </joint>
  <link
    name="hr_leg_l2">
    <inertial>
      <origin
        xyz="-0.027489 -0.092021 0.0051936"
        rpy="0 0 0" />
      <mass
        value="2.739" />
      <inertia
        ixx="0.00554"
        ixy="0.00278"
        ixz="-0.00146"
        iyy="0.01645"
        iyz="-0.00053"
        izz="0.01659" />
    </inertial>
    <visual>
      <origin
        xyz="0 0 0"
        rpy="0 0 0" />
      <geometry>
        <mesh
          filename="package://xpp_eqr2/meshes/hr_leg_l2.STL" />
      </geometry>
      <material
        name="">
        <color
          rgba="0.75294 0.75294 0.75294 1" />
      </material>
    </visual>
    <collision>
      <origin
        xyz="0 -0.09 0"
        rpy="1.5708 0 0" />
      <geometry>
        <cylinder
          radius="0.065"
          length="0.12" />
      </geometry>
    </collision>

    <collision>
      <origin
        xyz="-0.13 -0.13 0.03"
        rpy="0.0 0 0" />
      <geometry>
        <box
          size="0.11 0.05 0.05" />
      </geometry>
    </collision>
  </link>
  <joint
    name="hr_leg_2"
    type="revolute">
    <origin
      xyz="-0.075 -0.00975 0"
      rpy="0 0 0" />
    <parent
      link="hr_leg_l1" />
    <child
      link="hr_leg_l2" />
    <axis
      xyz="0 1 0" />
    <limit
      lower="-3.49"
      upper="1.84"
      effort="150"
      velocity="20" />
  </joint>
  <link
    name="hr_leg_l3">
    <inertial>
      <origin
        xyz="0.091028 -1E-05 -0.028535"
        rpy="0 0 0" />
      <mass
        value="0.37038" />
      <inertia
        ixx="0.00068"
        ixy="0"
        ixz="-0.00143"
        iyy="0.00433"
        iyz="0"
        izz="0.0037" />
    </inertial>
    <visual>
      <origin
        xyz="0 0 0"
        rpy="0 0 0" />
      <geometry>
        <mesh
          filename="package://xpp_eqr2/meshes/hr_leg_l3.STL" />
      </geometry>
      <material
        name="">
        <color
          rgba="0.75294 0.75294 0.75294 1" />
      </material>
    </visual>
    <collision>
      <origin
        xyz="0.1 0 -0.02"
        rpy="0 0 0" />
      <geometry>
        <box
          size="0.08 0.02 0.025" />
      </geometry>
    </collision>

    <collision>
      <origin
        xyz="0.18 0 -0.05"
        rpy="0 0.70 0" />
      <geometry>
        <box
          size="0.08 0.02 0.025" />
      </geometry>
    </collision>

    <collision>
      <origin
        xyz="0.025 0 -0.01"
        rpy="0 0.26 0" />
      <geometry>
        <box
          size="0.063 0.025 0.025" />
      </geometry>
    </collision>

    <collision>
      <origin
        xyz="-0.025 0 0.02"
        rpy="0 1.0 0" />
      <geometry>
        <box
          size="0.04 0.02 0.025" />
      </geometry>
    </collision>
  </link>
  <joint
    name="hr_leg_3"
    type="revolute">
    <origin
      xyz="-0.25 -0.12675 0"
      rpy="0 0 0" />
    <parent
      link="hr_leg_l2" />
    <child
      link="hr_leg_l3" />
    <axis
      xyz="0 1 0" />
    <limit
      lower="0"
      upper="1.86"
      effort="150"
      velocity="20" />
  </joint>
  <link
    name="hr_leg_lee">
    <inertial>
      <origin
        xyz="0.0055825 0.0001816 -0.011846"
        rpy="0 0 0" />
      <mass
        value="0.10556" />
      <inertia
        ixx="2E-05"
        ixy="0"
        ixz="1E-05"
        iyy="3E-05"
        iyz="0"
        izz="4E-05" />
    </inertial>
    <visual>
      <origin
        xyz="0 0 0"
        rpy="0 0 0" />
      <geometry>
        <mesh
          filename="package://xpp_eqr2/meshes/hr_leg_lee.STL" />
      </geometry>
      <material
        name="">
        <color
          rgba="0.75294 0.75294 0.75294 1" />
      </material>
    </visual>
    <collision>
      <origin
        xyz="0 0 0" rpy="0 0 0" />
      <geometry>
        <sphere
          radius="0.035" />
      </geometry>
    </collision>
  </link>
  <joint
    name="hr_leg_ee"
    type="fixed">
    <origin
      xyz="0.25045 0 -0.11113"
      rpy="0 0 0" />
    <parent
      link="hr_leg_l3" />
    <child
      link="hr_leg_lee" />
    <axis
      xyz="0 0 0" />
  </joint>
  <link
    name="rtk_1_lsensor">
    <inertial>
      <origin
        xyz="0 0 0.0013"
        rpy="0 0 0" />
      <mass
        value="0.00089107" />
      <inertia
        ixx="0"
        ixy="0"
        ixz="0"
        iyy="0"
        iyz="0"
        izz="0" />
    </inertial>
    <visual>
      <origin
        xyz="0 0 0"
        rpy="0 0 0" />
      <geometry>
        <mesh
          filename="package://xpp_eqr2/meshes/rtk_1_lsensor.STL" />
      </geometry>
      <material
        name="">
        <color
          rgba="1 1 1 1" />
      </material>
    </visual>
    <collision>
      <origin
        xyz="0 0 0"
        rpy="0 0 0" />
      <geometry>
        <mesh
          filename="package://xpp_eqr2/meshes/rtk_1_lsensor.STL" />
      </geometry>
    </collision>
  </link>
  <joint
    name="rtk_1_sensor"
    type="fixed">
    <origin
      xyz="-0.0435 -0.0398 0.0146"
      rpy="0 0 0" />
    <parent
      link="base_link" />
    <child
      link="rtk_1_lsensor" />
    <axis
      xyz="0 0 0" />
  </joint>
  <link
    name="laser_1_lsensor">
    <inertial>
      <origin
        xyz="-0.0002 -1E-05 -0.017644"
        rpy="0 0 0" />
      <mass
        value="0.26253" />
      <inertia
        ixx="7E-05"
        ixy="0"
        ixz="0"
        iyy="7E-05"
        iyz="0"
        izz="7E-05" />
    </inertial>
    <visual>
      <origin
        xyz="0 0 0"
        rpy="0 0 0" />
      <geometry>
        <mesh
          filename="package://xpp_eqr2/meshes/laser_1_lsensor.STL" />
      </geometry>
      <material
        name="">
        <color
          rgba="0.86667 0.9098 1 1" />
      </material>
    </visual>
    <collision>
      <origin
        xyz="0 -0.005 0.005"
        rpy="0 0 0" />
      <geometry>
        <box
          size="0.10 0.09 0.045" />
      </geometry>
    </collision>
  </link>
  <joint
    name="laser_1_sensor"
    type="fixed">
    <origin
      xyz="0.42262 0 -0.091198"
      rpy="-2.5482 0 -1.5708" />
    <parent
      link="base_link" />
    <child
      link="laser_1_lsensor" />
    <axis
      xyz="0 0 0" />
  </joint>
  <link
    name="laser_2_lsensor">
    <inertial>
      <origin
        xyz="-0.00021415 0.00020211 -0.0155"
        rpy="0 0 0" />
      <mass
        value="0.26253" />
      <inertia
        ixx="7E-05"
        ixy="0"
        ixz="0"
        iyy="7E-05"
        iyz="0"
        izz="7E-05" />
    </inertial>
    <visual>
      <origin
        xyz="0 0 0"
        rpy="0 0 0" />
      <geometry>
        <mesh
          filename="package://xpp_eqr2/meshes/laser_2_lsensor.STL" />
      </geometry>
      <material
        name="">
        <color
          rgba="0.86667 0.9098 1 1" />
      </material>
    </visual>
    <collision>
      <origin
        xyz="0 0 0"
        rpy="0 0 0" />
      <geometry>
        <box
          size="0.075 0.077 0.075" />
      </geometry>
    </collision>
  </link>
  <joint
    name="laser_2_sensor"
    type="fixed">
    <origin
      xyz="0.42159 0 0.050349"
      rpy="0 0.69813 0" />
    <parent
      link="base_link" />
    <child
      link="laser_2_lsensor" />
    <axis
      xyz="0 0 0" />
  </joint>
  <link
    name="laser_3_lsensor">
    <inertial>
      <origin
        xyz="-1E-05 0.0002 -0.01747"
        rpy="0 0 0" />
      <mass
        value="0.26253" />
      <inertia
        ixx="7E-05"
        ixy="0"
        ixz="0"
        iyy="7E-05"
        iyz="0"
        izz="7E-05" />
    </inertial>
    <visual>
      <origin
        xyz="0 0 0"
        rpy="0 0 0" />
      <geometry>
        <mesh
          filename="package://xpp_eqr2/meshes/laser_3_lsensor.STL" />
      </geometry>
      <material
        name="">
        <color
          rgba="0.86667 0.9098 1 1" />
      </material>
    </visual>
    <collision>
      <origin
        xyz="0 0 0"
        rpy="0 0 0" />
      <geometry>
        <box
          size="0.075 0.077 0.075" />
      </geometry>
    </collision>
  </link>
  <joint
    name="laser_3_sensor"
    type="fixed">
    <origin
      xyz="-0.4237 0 0.05199"
      rpy="0 0.69813 -3.1416" />
    <parent
      link="base_link" />
    <child
      link="laser_3_lsensor" />
    <axis
      xyz="0 0 0" />
  </joint>
  <link
    name="laser_4_lsensor">
    <inertial>
      <origin
        xyz="-0.0002 0.00976 -0.014637"
        rpy="0 0 0" />
      <mass
        value="0.26253" />
      <inertia
        ixx="7E-05"
        ixy="0"
        ixz="0"
        iyy="7E-05"
        iyz="0"
        izz="7E-05" />
    </inertial>
    <visual>
      <origin
        xyz="0 0 0"
        rpy="0 0 0" />
      <geometry>
        <mesh
          filename="package://xpp_eqr2/meshes/laser_4_lsensor.STL" />
      </geometry>
      <material
        name="">
        <color
          rgba="0.86667 0.9098 1 1" />
      </material>
    </visual>
    <collision>
      <origin
        xyz="0 -0.015 0.002"
        rpy="0.5 0 0" />
      <geometry>
        <box
          size="0.1 0.11 0.04" />
      </geometry>
    </collision>
  </link>
  <joint
    name="laser_4_sensor"
    type="fixed">
    <origin
      xyz="-0.42362 0 -0.091205"
      rpy="3.1416 0 1.5708" />
    <parent
      link="base_link" />
    <child
      link="laser_4_lsensor" />
    <axis
      xyz="0 0 0" />
  </joint>
  <link
    name="antennas_1_lsensor">
    <!-- <inertial>
      <origin
        xyz="0 0 0.028856"
        rpy="0 0 0" />
      <mass
        value="0.019578" />
      <inertia
        ixx="1E-05"
        ixy="0"
        ixz="0"
        iyy="1E-05"
        iyz="0"
        izz="0" />
    </inertial> -->
    <visual>
      <origin
        xyz="0 0 0"
        rpy="0 0 0" />
      <geometry>
        <mesh
          filename="package://xpp_eqr2/meshes/antennas_1_lsensor.STL" />
      </geometry>
      <material
        name="">
        <color
          rgba="1 1 1 1" />
      </material>
    </visual>
    <collision>
      <origin
        xyz="0 0 0.025"
        rpy="0 0 0" />
      <geometry>
        <cylinder
          radius="0.013"
          length="0.07" />
      </geometry>
    </collision>
  </link>
  <joint
    name="antennas_1_sensor"
    type="fixed">
    <origin
      xyz="0.3001 0 0.075994"
      rpy="0 0 0" />
    <parent
      link="base_link" />
    <child
      link="antennas_1_lsensor" />
    <axis
      xyz="0 0 0" />
  </joint>
  <link
    name="antennas_2_lsensor">
    <!-- <inertial>
      <origin
        xyz="0 0 0.028856"
        rpy="0 0 0" />
      <mass
        value="0.019578" />
      <inertia
        ixx="1E-05"
        ixy="0"
        ixz="0"
        iyy="1E-05"
        iyz="0"
        izz="0" />
    </inertial> -->
    <visual>
      <origin
        xyz="0 0 0"
        rpy="0 0 0" />
      <geometry>
        <mesh
          filename="package://xpp_eqr2/meshes/antennas_2_lsensor.STL" />
      </geometry>
      <material
        name="">
        <color
          rgba="1 1 1 1" />
      </material>
    </visual>
    <collision>
      <origin
        xyz="0 0 0.025"
        rpy="0 0 0" />
      <geometry>
        <cylinder
          radius="0.013"
          length="0.07" />
      </geometry>
    </collision>
  </link>
  <joint
    name="antennas_2_sensor"
    type="fixed">
    <origin
      xyz="-0.3011 0 0.075994"
      rpy="0 0 0" />
    <parent
      link="base_link" />
    <child
      link="antennas_2_lsensor" />
    <axis
      xyz="0 0 0" />
  </joint>
  <link
    name="d435i_1_lsensor">
    <inertial>
      <origin
        xyz="0.031655 8E-05 -0.0098426"
        rpy="0 0 0" />
      <mass
        value="0.072613" />
      <inertia
        ixx="1E-05"
        ixy="0"
        ixz="0"
        iyy="5E-05"
        iyz="0"
        izz="5E-05" />
    </inertial>
    <visual>
      <origin
        xyz="0 0 0"
        rpy="0 0 0" />
      <geometry>
        <mesh
          filename="package://xpp_eqr2/meshes/d435i_1_lsensor.STL" />
      </geometry>
      <material
        name="">
        <color
          rgba="0.86667 0.9098 1 1" />
      </material>
    </visual>
    <collision>
      <origin
        xyz="0.033 0 0.001"
        rpy="0.0 0 0" />
      <geometry>
        <box
          size="0.09 0.03 0.02" />
      </geometry>
    </collision>
  </link>
  <joint
    name="d435i_1_sensor"
    type="fixed">
    <origin
      xyz="0.46788 0.032488 -0.028575"
      rpy="-1.9199 0 -1.5708" />
    <parent
      link="base_link" />
    <child
      link="d435i_1_lsensor" />
    <axis
      xyz="0 0 0" />
  </joint>
  <link
    name="d435i_2_lsensor">
    <inertial>
      <origin
        xyz="0.031655 8E-05 -0.00984"
        rpy="0 0 0" />
      <mass
        value="0.072613" />
      <inertia
        ixx="1E-05"
        ixy="0"
        ixz="0"
        iyy="5E-05"
        iyz="0"
        izz="5E-05" />
    </inertial>
    <visual>
      <origin
        xyz="0 0 0"
        rpy="0 0 0" />
      <geometry>
        <mesh
          filename="package://xpp_eqr2/meshes/d435i_2_lsensor.STL" />
      </geometry>
      <material
        name="">
        <color
          rgba="0.86667 0.9098 1 1" />
      </material>
    </visual>
    <collision>
      <origin
        xyz="0 0 0"
        rpy="0 0 0" />
      <geometry>
        <mesh
          filename="package://xpp_eqr2/meshes/d435i_2_lsensor.STL" />
      </geometry>
    </collision>
  </link>
  <joint
    name="d435i_2_sensor"
    type="fixed">
    <origin
      xyz="0.031988 0.1236 0.025418"
      rpy="1.8326 0 3.1416" />
    <parent
      link="base_link" />
    <child
      link="d435i_2_lsensor" />
    <axis
      xyz="0 0 0" />
  </joint>
  <link
    name="d435i_3_lsensor">
    <inertial>
      <origin
        xyz="0.03166 8E-05 -0.00984"
        rpy="0 0 0" />
      <mass
        value="0.072613" />
      <inertia
        ixx="1E-05"
        ixy="0"
        ixz="0"
        iyy="5E-05"
        iyz="0"
        izz="5E-05" />
    </inertial>
    <visual>
      <origin
        xyz="0 0 0"
        rpy="0 0 0" />
      <geometry>
        <mesh
          filename="package://xpp_eqr2/meshes/d435i_3_lsensor.STL" />
      </geometry>
      <material
        name="">
        <color
          rgba="0.86667 0.9098 1 1" />
      </material>
    </visual>
    <collision>
      <origin
        xyz="0 0 0"
        rpy="0 0 0" />
      <geometry>
        <mesh
          filename="package://xpp_eqr2/meshes/d435i_3_lsensor.STL" />
      </geometry>
    </collision>
  </link>
  <joint
    name="d435i_3_sensor"
    type="fixed">
    <origin
      xyz="-0.032988 -0.1236 0.025418"
      rpy="1.8326 0 0" />
    <parent
      link="base_link" />
    <child
      link="d435i_3_lsensor" />
    <axis
      xyz="0 0 0" />
  </joint>
  <link
    name="d435i_4_lsensor">
    <inertial>
      <origin
        xyz="0.03166 8E-05 -0.00984"
        rpy="0 0 0" />
      <mass
        value="0.072613" />
      <inertia
        ixx="1E-05"
        ixy="0"
        ixz="0"
        iyy="5E-05"
        iyz="0"
        izz="5E-05" />
    </inertial>
    <visual>
      <origin
        xyz="0 0 0"
        rpy="0 0 0" />
      <geometry>
        <mesh
          filename="package://xpp_eqr2/meshes/d435i_4_lsensor.STL" />
      </geometry>
      <material
        name="">
        <color
          rgba="1 1 1 1" />
      </material>
    </visual>
    <collision>
      <origin
        xyz="0.033 0 0.001"
        rpy="0.0 0 0" />
      <geometry>
        <box
          size="0.09 0.03 0.02" />
      </geometry>
    </collision>
  </link>
  <joint
    name="d435i_4_sensor"
    type="fixed">
    <origin
      xyz="-0.46888 -0.032488 -0.028575"
      rpy="-1.9199 0 1.5708" />
    <parent
      link="base_link" />
    <child
      link="d435i_4_lsensor" />
    <axis
      xyz="0 0 0" />
  </joint>
</robot>
